<?xml version="1.0" ?>

<robot xmlns:xacro="http://ros.org/wiki/xacro" >

  <xacro:macro name="hokuyo_caster"
               params="parent *origin" >

    <link name="laser_link" >

      <inertial>
        <mass value="0.01" />
        <origin xyz="0 0 0" />
        <inertia ixx="0.0002632"
                 ixy="0"
                 ixz="0"
                 iyy="0.0002632"
                 iyz="0"
                 izz="0.000162" />
      </inertial>

      <visual name="visual" >
        <geometry>
          <mesh filename="package://pandora_sensors_description/meshes/hokuyo_utm_30lx/hokuyo_utm_30lx.dae" />
        </geometry>
      </visual>

      <collision name="collision-base" >
        <origin xyz="0 0 -0.0145"
                rpy="0 0 0" />
        <geometry>
      <box size="0.05 0.05 0.041" />
        </geometry>
      </collision>

      <collision name="collision-top" >
        <origin xyz="0 0 0.0205"
                rpy="0 0 0" />
        <geometry>
          <cylinder radius="0.021"
                    length="0.029" />
        </geometry>
      </collision>

    </link>

    <gazebo reference="laser_link" >

      <sensor name="laser"
              type="ray" >

        <pose>0.01 0 0.0175 0 -0 0</pose>

        <ray>

          <scan>
            <horizontal>
              <samples>640</samples>
              <resolution>1</resolution>
              <min_angle>-2.26889</min_angle>
              <max_angle>2.268899</max_angle>
            </horizontal>
          </scan>

          <range>
            <min>0.08</min>
            <max>10</max>
            <resolution>0.01</resolution>
          </range>

        </ray>

        <plugin name="laser"
                filename="libRayPlugin.so" />

        <plugin name="laser2Ros"
                filename="libgazebo_ros_laser.so" >

          <topicName>/slam/scan</topicName>
          <frameName>/laser_link</frameName>

        </plugin>

        <always_on>1</always_on>
        <update_rate>30</update_rate>
        <visualize>true</visualize>

      </sensor>

    </gazebo>

    <link name="hokuyo_base_link" >

      <inertial>
        <mass value="0.001" />
        <origin xyz="0 0 0" />
        <inertia ixx="0.00000001"
                 ixy="0"
                 ixz="0"
                 iyy="0.00000001"
                 iyz="0"
                 izz="0.00000001" />
      </inertial>

      <visual>
        <origin xyz="0 0 0"
                rpy="0 0 0" />
        <geometry>
          <box size="0 0 0" />
        </geometry>
      </visual>

      <collision>
        <origin xyz="0 0 0"
                rpy="0 0 0" />
        <geometry>
          <box size="0 0 0" />
        </geometry>
      </collision>

    </link>

    <joint name="laser_roll_joint"
           type="revolute" >

      <parent link="${parent}" />
      <child link="hokuyo_base_link" />

      <xacro:insert_block name="origin" />

      <axis xyz="1 0 0" />
      <limit lower="-1.57"
             upper="1.57"
             effort="300"
             velocity="100.0" />

    </joint>

    <joint name="laser_pitch_joint"
           type="revolute" >

      <parent link="hokuyo_base_link" />
      <child link="laser_link" />

      <origin xyz="0 0 0" rpy="0 0 0" />

      <axis xyz="0 1 0" />
      <limit lower="-1.57"
             upper="1.57"
             effort="300"
             velocity="100.0" />

    </joint>

  </xacro:macro>

</robot>
