<?xml version="1.0"?>

<robot name="pioneer3at"
       xmlns:xacro="http://ros.org/wiki/xacro" >
  
<!-- Links and Joints ##################################################### -->

  <!-- Base =============================================================== --> 
  <link name="base_link" >
  
    <inertial>
      <mass value="14.0" />
      <origin xyz="0 0 0"
              rpy="0 0 0" />
      <inertia ixx="0.3338"
               ixy="0"
               ixz="0"
               iyy="0.4783"
               iyz="0"
               izz="0.3338" />
    </inertial>
    
    <visual>
      <origin xyz="0 0 0"
              rpy="0 0 0" />
      <geometry>
        <mesh filename="package://pandora_robots_description/meshes/pioneer3at/p3at_meshes/chassis.stl" />
      </geometry>
      <material name="ChassisRed" >
        <color rgba="0.851 0.0 0.0 1.0" />
      </material>
    </visual>
    
    <collision>
      <origin xyz="0 0 0"
              rpy="0 0 0" />
      <geometry>
        <mesh filename="package://pandora_robots_description/meshes/pioneer3at/p3at_meshes/chassis.stl" />
      </geometry>
    </collision>
    
  </link>

  <gazebo reference="base_link" >
  
    <material value="Gazebo/Red" />
    
  </gazebo>
  
  <!-- Top ================================================================ --> 
  <link name="top_plate" >
  
    <inertial>
      <mass value="0.1" />	
      <origin xyz="0 0 0"
              rpy="0 0 0" />
      <inertia ixx="0.001"
               ixy="0.0"
               ixz="0.0"
               iyy="0.001"
               iyz="0.0"
               izz="0.001" />
    </inertial>
    
    <visual>
      <origin xyz="0 0 0"
              rpy="0 0 0" />
      <geometry>
        <mesh filename="package://pandora_robots_description/meshes/pioneer3at/p3at_meshes/top.stl" />
      </geometry>
      <material name="TopBlack" >
          <color rgba="0.038 0.038 0.038 1.0" />
      </material>
    </visual>
    
    <collision>
      <origin xyz="0 0 0"
              rpy="0 0 0" />
      <geometry>
        <box size="0 0 0" />
      </geometry>
    </collision>
    
  </link>
  
  <gazebo reference="top_plate" >
  
    <material value="Gazebo/Black" />
    
  </gazebo>

  <joint name="base_top_joint"
         type="fixed" >
  
    <parent link="base_link" />
    <child link="top_plate" />
    <origin xyz="-0.025 0 0.096" />
    
  </joint>

  <!-- Front Axles + Wheels + Hubcaps ===================================== --> 
  <xacro:macro name="p3at_front"
               params="suffix reflect" >
  
    <link name="p3at_front_${suffix}_axle" >
    
      <inertial>
        <mass value="0.1" />	
        <origin xyz="0 0 0"
                rpy="0 0 0" />
        <inertia ixx="0.001"
                 ixy="0.0"
                 ixz="0.0"
                 iyy="0.001"
                 iyz="0.0"
                 izz="0.001" />
      </inertial>
        
      <visual>
        <origin xyz="0 0 0"
                rpy="0 0 0" />
        <geometry>
          <mesh filename="package://pandora_robots_description/meshes/pioneer3at/p3at_meshes/axle.stl" />
        </geometry>
        <material name="AxleGrey" >
          <color rgba="0.5 0.5 0.5 1" />
        </material>
      </visual>
      
      <collision>
        <origin xyz="0 0 0"
                rpy="0 0 0" />
        <geometry>
          <box size="0 0 0" />
        </geometry>
      </collision>
    
    </link>
    
    <gazebo reference="p3at_front_${suffix}_axle" >
    
      <material value="Gazebo/Grey" />
      
    </gazebo>
  
    <joint name="base_front_${suffix}_axle_joint"
           type="fixed" >
    
      <parent link="base_link" />
      <child link="p3at_front_${suffix}_axle" />
      <origin xyz="0.135 ${reflect*0.156} -0.066"
              rpy="0 0 0" />
      
    </joint>
  
    <link name="p3at_front_${suffix}_hub" >
    
      <inertial>
        <mass value="0.1" />	
        <origin xyz="0 0 0"
                rpy="0 0 0" />
        <inertia ixx="0.001"
                 ixy="0.0"
                 ixz="0.0"
                 iyy="0.001"
                 iyz="0.0"
                 izz="0.001" />
      </inertial>
      
      <visual>
        <origin xyz="0 0 0"
                rpy="0 0 0" />
        <geometry>
          <mesh filename="package://pandora_robots_description/meshes/pioneer3at/p3at_meshes/${suffix}_hubcap.stl" />
        </geometry>
        <material name="HubcapYellow" >
          <color rgba="1.0 0.811 0.151 1.0" />
        </material>
      </visual>
      
      <collision>
        <origin xyz="0 0 0"
                rpy="0 0 0" />
        <geometry>
          <box size="0 0 0" />
        </geometry>
      </collision>
      
    </link>
    
    <gazebo reference="p3at_front_${suffix}_hub" >
    
      <material value="Gazebo/Yellow" />
      
    </gazebo>
  
    <joint name="base_front_${suffix}_hub_joint"
           type="fixed" >
    
      <parent link="p3at_front_${suffix}_axle" />
      <child link="p3at_front_${suffix}_hub" />
      <origin xyz="0 ${reflect*0.041} 0"
              rpy="0 0 0" />
      
    </joint>
  
    <link name="p3at_front_${suffix}_wheel" >
    
      <inertial>
        <mass value="0.5" />	
        <origin xyz="0 0 0"
                rpy="0 0 0" />
        <inertia ixx="0.012411765597"
                 ixy="0"
                 ixz="0"
                 iyy="0.015218160428"
                 iyz="0"
                 izz="0.011763977943" />
      </inertial>
      
      <visual>
        <origin xyz="0 0 0"
                rpy="0 0 0" />
        <geometry>
          <mesh filename="package://pandora_robots_description/meshes/pioneer3at/p3at_meshes/wheel.stl" />
        </geometry>
        <material name="WheelBlack" >
          <color rgba="0.117 0.117 0.117 1" />
        </material>
      </visual>
      
      <collision>
        <origin xyz="0 0 0"
                rpy="${-3.1415927/2} 0 0" />
        <geometry>
          <!--mesh filename="package://pandora_robots_description/meshes/pioneer3at/p3at_meshes/wheel.stl"/-->
          <cylinder radius="0.111"
                    length="0.075" />
        </geometry>
      </collision>
      
    </link>
    
    <gazebo reference="p3at_front_${suffix}_wheel" >
    
      <material value="Gazebo/Black" />
      
    </gazebo>
  
    <joint name="p3at_front_${suffix}_wheel_joint"
           type="continuous" >
    
      <parent link="p3at_front_${suffix}_hub" />
      <child link="p3at_front_${suffix}_wheel" />
      <origin xyz="0 0 0"
              rpy="0 0 0" />
      <axis xyz="0 1 0" />
      <limit effort="100"
             velocity="100" />
      <joint_properties damping="0.7" />
      
    </joint>
    
    <!-- Back Axles + Wheels + Hubcaps ==================================== --> 
    <link name="p3at_back_${suffix}_axle" >
    
      <inertial>
        <mass value="0.1" />	
        <origin xyz="0 0 0"
                rpy="0 0 0" />
        <inertia ixx="0.001"
                 ixy="0.0"
                 ixz="0.0"
                 iyy="0.001"
                 iyz="0.0"
                 izz="0.001" />
      </inertial>
      
      <visual>
        <origin xyz="0 0 0"
                rpy="0 0 0" />
        <geometry>
          <mesh filename="package://pandora_robots_description/meshes/pioneer3at/p3at_meshes/axle.stl" />
        </geometry>
        <material name="AxleGrey" >
          <color rgba="0.5 0.5 0.5 1" />
        </material>
      </visual>
      
      <collision>
        <origin xyz="0 0 0"
                rpy="0 0 0" />
        <geometry>
          <mesh filename="package://pandora_robots_description/meshes/pioneer3at/p3at_meshes/axle.stl" />
        </geometry>
      </collision>
      
    </link>
    
    <gazebo reference="p3at_back_${suffix}_axle" >
    
      <material value="Gazebo/Grey" />
      
    </gazebo>
  
    <joint name="bp3at_back_${suffix}_axle_joint"
           type="fixed" >
    
      <parent link="base_link" />
      <child link="p3at_back_${suffix}_axle" />
      <origin xyz="-0.134 ${reflect*0.156} -0.066"
              rpy="0 0 0" />
      
    </joint>
  
    <link name="p3at_back_${suffix}_hub" >
    
      <inertial>
        <mass value="0.1" />	
        <origin xyz="0 0 0"
                rpy="0 0 0" />
        <inertia ixx="0.001"
                 ixy="0.0"
                 ixz="0.0"
                 iyy="0.001"
                 iyz="0.0"
                 izz="0.001" />
      </inertial>
      
      <visual>
        <origin xyz="0 0 0"
                rpy="0 0 0" />
        <geometry>
          <mesh filename="package://pandora_robots_description/meshes/pioneer3at/p3at_meshes/${suffix}_hubcap.stl" />
        </geometry>
        <material name="HubcapYellow" />
      </visual>
      
      <collision>
        <origin xyz="0 0 0"
                rpy="0 0 0" />
        <geometry>
          <mesh filename="package://pandora_robots_description/meshes/pioneer3at/p3at_meshes/${suffix}_hubcap.stl" />
        </geometry>
      </collision>
      
    </link>
    
    <gazebo reference="p3at_back_${suffix}_hub" >
    
      <material value="Gazebo/Yellow" />
      
    </gazebo>
  
    <joint name="p3at_back_${suffix}_hub_joint"
           type="fixed" >
           
      <parent link="p3at_back_${suffix}_axle" />
      <child link="p3at_back_${suffix}_hub" />
      <origin xyz="-0 ${reflect*0.041} 0"
              rpy="0 0 0" />
              
    </joint>
  
    <link name="p3at_back_${suffix}_wheel" >
    
      <inertial>
        <mass value="0.5" />	
        <origin xyz="0 0 0"
                rpy="0 0 0" />
        <inertia ixx="0.012411765597"
                 ixy="0"
                 ixz="0"
                 iyy="0.015218160428"
                 iyz="0"
                 izz="0.011763977943" />
      </inertial>
      
      <visual>
        <origin xyz="0 0 0"
                rpy="0 0 0" />
        <geometry>
          <mesh filename="package://pandora_robots_description/meshes/pioneer3at/p3at_meshes/wheel.stl" />
        </geometry>
      </visual>
      
      <collision>
        <origin xyz="0 0 0"
                rpy="${-3.1415927/2} 0 0" />
        <geometry>
          <!--<mesh filename="package://pandora_robots_description/meshes/pioneer3at/p3at_meshes/wheel.stl" />-->
          <cylinder radius="0.111"
                    length="0.075" />
        </geometry>
      </collision>
      
    </link>
    
    <gazebo reference="p3at_back_${suffix}_wheel" >
    
      <material value="Gazebo/Black" />
      
    </gazebo>
  
    <joint name="p3at_back_${suffix}_wheel_joint"
           type="continuous" >
           
      <parent link="p3at_back_${suffix}_hub" />
      <child link="p3at_back_${suffix}_wheel" />
      <origin xyz="0 0 0"
              rpy="0 0 0" />
      <axis xyz="0 1 0" />
      <limit effort="100"
             velocity="100" />
      <joint_properties damping="0.7" />
      
    </joint>
    
    <!-- Wheel Physics ==================================================== --> 
    <gazebo reference="p3at_back_${suffix}_wheel" >
    
      <kp>1000000.0</kp> <!-- kp and kd for rubber -->
      <kd>100.0</kd>
      <mu1>10.0</mu1>
      <mu2>1.0</mu2>
      <!-- <fdir1>0 1 0</fdir1> -->
      <maxVel>1.0</maxVel>
      <minDepth>0.00</minDepth>
      
    </gazebo>
    
    <gazebo reference="p3at_front_${suffix}_wheel" >
    
      <kp>1000000.0</kp> <!-- kp and kd for rubber -->
      <kd>100.0</kd>
      <mu1>10.0</mu1>
      <mu2>1.0</mu2>
      <!-- <fdir1>0 1 0</fdir1> -->
      <maxVel>1.0</maxVel>
      <minDepth>0.00</minDepth>
      
    </gazebo>
    
    <!-- Wheel Transmission =============================================== -->
    <xacro:if value="$(arg control)" >
    
      <transmission name="p3at_front_${suffix}_wheel_transmission" >
      
        <type>transmission_interface/SimpleTransmission</type>
        <joint name="p3at_front_${suffix}_wheel_joint" />
        <actuator name="p3at_front_${suffix}_motor" >
          <hardwareInterface>EffortJointInterface</hardwareInterface>
          <mechanicalReduction>1</mechanicalReduction>
        </actuator>
        
      </transmission>
      
      <transmission name="p3at_back_${suffix}_wheel_transmission" >
      
        <type>transmission_interface/SimpleTransmission</type>
        <joint name="p3at_back_${suffix}_wheel_joint" />
        <actuator name="p3at_back_${suffix}_motor" >
          <hardwareInterface>EffortJointInterface</hardwareInterface>
          <mechanicalReduction>1</mechanicalReduction>
        </actuator>
        
      </transmission>
      
    </xacro:if>
    
  </xacro:macro>

  <!-- Add Wheels ========================================================= --> 
  <xacro:p3at_front suffix="left" reflect="1" />
  <xacro:p3at_front suffix="right" reflect="-1" />
  <xacro:p3at_back suffix="left" reflect="1" />
  <xacro:p3at_back suffix="right" reflect="-1" />
  
<!-- Plugins ############################################################## -->
  
  <!-- Ros Control ======================================================== -->
  <xacro:if value="$(arg control)" >
  
    <gazebo>
    
      <plugin name="gazebo_ros_control" filename="libgazebo_ros_control.so" >
        <robotNamespace></robotNamespace>
      </plugin>
      
    </gazebo>
      
  </xacro:if>
  
  <!-- Skid Steer Drive =================================================== --> 
  <gazebo>
  
    <plugin name="RosSkidSteerDrivePlugin" filename="libgazebo_ros_skid_steer_drive.so" >
      <updateRate>50.0</updateRate>
      <robotNamespace></robotNamespace>
      <leftFrontJoint>p3at_front_left_wheel_joint</leftFrontJoint>
      <rightFrontJoint>p3at_front_right_wheel_joint</rightFrontJoint>
      <leftRearJoint>p3at_back_left_wheel_joint</leftRearJoint>
      <rightRearJoint>p3at_back_right_wheel_joint</rightRearJoint>
      <wheelSeparation>0.4</wheelSeparation>
      <wheelDiameter>0.220</wheelDiameter>
      <robotBaseFrame>base_link</robotBaseFrame>
      <topicName>cmd_vel</topicName>
      <broadcastTF>0</broadcastTF>
      <torque>5.0</torque>
      <commandTopic>cmd_vel</commandTopic>
      <odometryTopic>odom</odometryTopic>
      <odometryFrame>odom</odometryFrame>
    </plugin>
    
  </gazebo>
  
  <!-- 3D Pose ============================================================ --> 
  <gazebo>
  
    <plugin name="Pandora3dPosePlugin" filename="libpandora_p3d_plugin.so" >
      <robotNamespace></robotNamespace>
      <bodyName>base_link</bodyName>
      <frameName>map</frameName>
      <topicName>perfect_pose</topicName>
      <broadcastTF>0</broadcastTF>
    </plugin>
    
  </gazebo>
  
  <!-- Imu ================================================================ --> 
  <gazebo>
  
    <plugin filename="libgazebo_ros_imu.so" name="imu_en_ros" >
      <updateRate>50.0</updateRate>
      <topicName>/sensors/imu</topicName>
      <serviceName>default_imu</serviceName>
      <robotNamespace></robotNamespace>
      <bodyName>base_link</bodyName>
      <gaussianNoise>0.0</gaussianNoise>
      <xyzOffset>0 0 0</xyzOffset>
      <rpyOffset>0 0 0</rpyOffset>
    </plugin>
    
  </gazebo>

<!-- Sensors ############################################################## -->
  
  <!-- Sensor Transmission ================================================ --> 
  <xacro:macro name="sensor_transmission"
               params="sensor rotation" >
               
    <transmission name="${sensor}_${rotation}_transmission" >
    
      <type>transmission_interface/SimpleTransmission</type>
      <joint name="${sensor}_${rotation}_joint" />
      <actuator name="${sensor}_${rotation}_motor" >
        <hardwareInterface>EffortJointInterface</hardwareInterface>
        <mechanicalReduction>1.0</mechanicalReduction>
      </actuator>
      
    </transmission>
    
  </xacro:macro>
  
  <!-- Kinect ============================================================= --> 
  <xacro:include filename="$(find pandora_sensors_description)/urdf/kinect_camera.urdf.xacro" />
  
  <xacro:kinect_caster parent="base_link" >
  
    <origin xyz="0.2 0 0.33" rpy="0 0 0" />
    
  </xacro:kinect_caster>
  
  <xacro:if value="$(arg control)" >
  
    <xacro:sensor_transmission sensor="kinect" rotation="pitch" />
    <xacro:sensor_transmission sensor="kinect" rotation="yaw" />
      
  </xacro:if>
  
  <!-- Hokuyo Laser ======================================================= --> 
  <xacro:include filename="$(find pandora_sensors_description)/urdf/hokuyo_utm_30lx.urdf.xacro" />
  
  <xacro:hokuyo_caster parent="base_link" >
  
    <origin xyz="0.25 0 0.15" rpy="0 0 0" />
    
  </xacro:hokuyo_caster>
  
  <xacro:if value="$(arg control)" >
    
    <xacro:sensor_transmission sensor="laser" rotation="roll" />
    <xacro:sensor_transmission sensor="laser" rotation="pitch" />
      
  </xacro:if>
  
  <!-- Sonars ============================================================= --> 
  <xacro:include filename="$(find pandora_sensors_description)/urdf/sonar_sensor.urdf.xacro" />
  
  <xacro:sonar_caster name="left_rear" parent="base_link" >
  
    <origin xyz="-0.2 0.15 0.13" rpy="0 0 3.14" />
    
  </xacro:sonar_caster>
  
  <xacro:sonar_caster name="right_rear" parent="base_link" >
  
    <origin xyz="-0.2 -0.15 0.13" rpy="0 0 3.14" />
    
  </xacro:sonar_caster>
  
  <!-- Thermal ============================================================ --> 
  <xacro:include filename="$(find pandora_sensors_description)/urdf/thermal_sensor.urdf.xacro" />
  
  <xacro:thermal_caster parent="base_link" >
  
    <origin xyz="0.2 -0.05 0.23" rpy="0 0 0" />
    
  </xacro:thermal_caster>
  
  <!-- CO2 ================================================================ --> 
  <xacro:include filename="$(find pandora_sensors_description)/urdf/co2_sensor.urdf.xacro" />
  
  <xacro:co2_caster parent="base_link" >
  
    <origin xyz="0.2 0 0.36" rpy="0 0 0" />
    
  </xacro:co2_caster>
  
  <!-- Microphone ========================================================= --> 
  <xacro:include filename="$(find pandora_sensors_description)/urdf/microphone_sensor.urdf.xacro" />
  
  <xacro:microphone_caster parent="base_link" >
  
    <origin xyz="0.2 0 0.38" rpy="0 0 0" />
    
  </xacro:microphone_caster>

<!-- ###################################################################### -->
  
</robot>
