<?xml version="1.0" ?>

<robot xmlns:xacro="http://ros.org/wiki/xacro" >

  <xacro:macro name="asus_xtion_pro_live"
               params="parent *origin
                       pitch_min_limit pitch_max_limit
                       yaw_min_limit yaw_max_limit" >

    <!-- Links -->
    <link name="kinect_yaw_servo_link" >
      <xacro:solid_cuboid_inertial mass="0.055" x="0.050" y="0.032" z="0.049" >
        <origin xyz="-0.01316 0.00002 0.00093" />
      </xacro:solid_cuboid_inertial>
      <visual>
        <geometry>
          <mesh filename="package://pandora_sensors_description/kinect/meshes/yaw_servo_motor.dae" />
        </geometry>
      </visual>
      <collision>
        <origin xyz="-0.0135 0.0 -0.0028" />
        <geometry>
          <box size="0.050 0.032 0.049" />
        </geometry>
      </collision>
    </link>

    <link name="kinect_pitch_servo_link" >
      <xacro:solid_cuboid_inertial mass="0.063" x="0.043" y="0.041" z="0.070" >
        <origin xyz="0.0001 0.00217 -0.01699" />
      </xacro:solid_cuboid_inertial>
      <visual>
        <geometry>
          <mesh filename="package://pandora_sensors_description/kinect/meshes/pitch_servo_motor.dae" />
        </geometry>
      </visual>
      <collision>
        <origin xyz="0.0055 0.0 -0.0405" />
        <geometry>
          <box size="0.043 0.041 0.104" />
        </geometry>
      </collision>
    </link>

    <link name="kinect_platform_link" >
      <xacro:solid_cuboid_inertial mass="0.070" x="0.100" y="0.120" z="0.017" >
        <origin xyz="0.00926 -0.00059 -0.00362" />
      </xacro:solid_cuboid_inertial>
      <visual>
        <geometry>
          <mesh filename="package://pandora_sensors_description/kinect/meshes/platform.dae" />
        </geometry>
      </visual>
      <collision>
        <origin xyz="0.0095 0.0 0.04851"
                rpy="0 0 0" />
        <geometry>
          <box size="0.096 0.180 0.043" />
        </geometry>
      </collision>
    </link>

    <link name="kinect_link" >
      <xacro:solid_cuboid_inertial mass="0.2268" x="0.036" y="0.180" z="0.025" >
        <origin xyz="0.0000013 0.0 0.0000014" />
      </xacro:solid_cuboid_inertial>
      <visual>
        <geometry>
          <mesh filename="package://pandora_sensors_description/kinect/meshes/asus_xtion_pro_live.dae" />
        </geometry>
      </visual>
      <collision>
        <origin xyz="-0.00075 -0.00048 0.00016"
                rpy="0 0 0" />
        <geometry>
          <box size="0.036 0.180 0.025" />
        </geometry>
      </collision>
    </link>

    <!-- Joints -->
    <joint name="kinect_servo_parent_joint"
           type="fixed" >
      <parent link="${parent}" />
      <child link="kinect_yaw_servo_link" />
      <xacro:insert_block name="origin" />
    </joint>

    <joint name="kinect_yaw_joint"
           type="revolute" >
      <parent link="kinect_yaw_servo_link" />
      <child link="kinect_pitch_servo_link" />
      <origin xyz="0.0 0.0 0.06749"
              rpy="0.0 0.0 0.0" />
      <axis xyz="0 0 1" />
      <limit lower="${yaw_min_limit}"
             upper="${yaw_max_limit}"
             effort="50"
             velocity="50.0" />
    </joint>

    <joint name="kinect_pitch_joint"
           type="revolute" >
      <parent link="kinect_pitch_servo_link" />
      <child link="kinect_platform_link" />
      <origin xyz="0.0 0.0 0.0"
              rpy="0.0 -0.0174 0.0" />
      <axis xyz="0 1 0" />
      <limit lower="${pitch_min_limit}"
             upper="${pitch_max_limit}"
             effort="50"
             velocity="50.0" />
    </joint>

    <joint name="kinect_platform_joint"
           type="fixed" >
      <parent link="kinect_platform_link" />
      <child link="kinect_link" />
      <origin xyz="0.01461 -0.00106 0.05011"
              rpy="0.0 0.0674 0.0" />
    </joint>

    <!-- Frames -->
    <link name="kinect_frame" >
      <xacro:point_mass_inertial />
    </link>

    <link name="kinect_optical_frame" >
      <xacro:point_mass_inertial />
    </link>

    <link name="kinect_depth_frame" >
      <xacro:point_mass_inertial />
    </link>

    <link name="kinect_depth_optical_frame" >
      <xacro:point_mass_inertial />
    </link>

    <link name="kinect_rgb_frame" >
      <xacro:point_mass_inertial />
    </link>

    <link name="kinect_rgb_optical_frame" >
      <xacro:point_mass_inertial />
    </link>

    <joint name="kinect_joint"
           type="fixed" >
      <parent link="kinect_link" />
      <child link="kinect_frame" />
      <origin xyz="0.01784 0.0 0.02167"
              rpy="0.0 0.0 0.0" />
    </joint>
    <joint name="kinect_optical_joint"
           type="fixed" >
      <parent link="kinect_frame" />
      <child link="kinect_optical_frame" />
      <origin xyz="0.0 0.0 0.0"
              rpy="-1.5708 0.0 -1.5708" />
    </joint>

    <joint name="kinect_depth_joint"
           type="fixed" >
      <parent link="kinect_frame" />
      <child link="kinect_depth_frame" />
      <origin xyz="0.0 0.044 0.0"
              rpy="0.0 0.0 0.0" />
    </joint>
    <joint name="kinect_depth_optical_joint"
           type="fixed" >
      <parent link="kinect_depth_frame" />
      <child link="kinect_depth_optical_frame" />
      <origin xyz="0.0 0.0 0.0"
              rpy="-1.5708 0.0 -1.5708" />
    </joint>

    <joint name="kinect_rgb_joint"
           type="fixed" >
      <parent link="kinect_frame" />
      <child link="kinect_rgb_frame" />
      <origin xyz="0.0 0.019 0.0"
              rpy="0.0 0.0 0.0" />
    </joint>
    <joint name="kinect_rgb_optical_joint"
           type="fixed" >
      <parent link="kinect_rgb_frame" />
      <child link="kinect_rgb_optical_frame" />
      <origin xyz="0.0 0.0 0.0"
              rpy="-1.5708 0.0 -1.5708" />
    </joint>

  </xacro:macro>

</robot>
